<?xml version="1.0"?>
<robot xmlns:xacro="http://www.ros.org/wiki/xacro">

  <xacro:include filename="$(find rbvogui_description)/urdf/wheels/wheel.gazebo.xacro" />

  <xacro:property name="wheel_radius" value="0.1425" />

  <xacro:macro name="wheel_285mm" params="prefix parent *origin reflect hq">
    <xacro:macro name="cylinder_inertia" params="m r h">
      <inertia ixx="${m*(3*r*r+h*h)/12}" ixy = "0" ixz = "0" iyy="${m*(3*r*r+h*h)/12}" iyz = "0" izz="${m*r*r/2}" />
    </xacro:macro>

    <xacro:property name="M_PI" value="3.1415926535897931" />
    
    <xacro:property name="wheel_width" value="0.14" />
    <xacro:property name="wheel_mass" value="4.0" />

    <xacro:property name="wheel_joint_damping" value="0.1" />
    <xacro:property name="wheel_joint_friction" value="0.1" />
    <xacro:property name="wheel_joint_effort_limit" value="1000.0" />
    <xacro:property name="wheel_joint_velocity_limit" value="2000.0" />

    <!--WHEEL TIRE -->
    <joint name="${prefix}wheel_joint" type="continuous">
      <parent link="${parent}"/>
      <child link="${prefix}wheel"/>
      <xacro:insert_block name="origin" />
      <axis xyz="0 1 0" rpy="0 0 0" />
      <limit effort="${wheel_joint_effort_limit}" velocity="${wheel_joint_velocity_limit}"/>
      <dynamics damping="${wheel_joint_damping}" friction="${wheel_joint_friction}"/>
    </joint>

    <link name="${prefix}wheel">
      <visual>
        <material name="dark-gray">
          <color rgba="0.25 0.25 0.25 1.0"/>
        </material>
        <!-- HIGH RESOLUTION WHEELS -->
        <xacro:if value="${hq}">
		      <xacro:if value="${reflect}">
			      <origin xyz="0 0 0" rpy="0 0 ${M_PI}" />
		      </xacro:if>
          <xacro:unless value="${reflect}">
            <origin xyz="0 0 0" rpy="0 0 0" />
          </xacro:unless>
          <geometry>
            <mesh filename="package://rbvogui_description/meshes/wheels/wheel_285mm.stl" />
          </geometry>
        </xacro:if>
        <!-- LOW RESOLUTION WHEELS -->
        <xacro:unless value="${hq}">
          <origin xyz="0 0 0" rpy="${M_PI/2} 0 0" />
          <geometry>
            <cylinder length="${wheel_width}" radius="${wheel_radius}" />
          </geometry>
        </xacro:unless>
        <material name="black_wheel">
          <color rgba="0.1 0.1 0.1 1"/>     
        </material>
      </visual>
      <collision>
        <origin xyz="0 0 0" rpy="${M_PI/2} 0 0" />
        <geometry>
          <cylinder length="${wheel_radius}" radius="${wheel_radius}" />
        </geometry>
      </collision>
      <inertial>
        <mass value="${wheel_mass}" />
        <origin xyz="0 0 0" rpy="${M_PI/2} 0 0"/>
        <xacro:cylinder_inertia m="${wheel_mass}" r="${wheel_radius}" h="${wheel_width}" />
      </inertial>
    </link>

    <!-- GAZEBO PARAMETERS -->
    <xacro:gazebo_rubber_tire_physics name="${prefix}wheel" />
    <xacro:gazebo_rubber_tire_material name="${prefix}wheel" />
  </xacro:macro>
</robot>
