<?xml version="1.0"?>
<robot xmlns:xacro="http://wiki.ros.org/xacro">

  <xacro:include filename="$(find rbvogui_description)/urdf/wheels/wheel.gazebo.xacro" />

  <xacro:property name="M_PI" value="3.1415926535897931" />
  <!-- Wheels -->
  <xacro:property name="wheel_radius" value="0.17" />
  <xacro:property name="wheel_width" value="0.14" />
  <xacro:property name="wheel_mass" value="4.0" />
  <!-- in kg-->

  <xacro:property name="steer_joint_damping" value="2.0" />
  <xacro:property name="steer_joint_friction" value="1.0" />
  <xacro:property name="steer_joint_effort_limit" value="100.0" />
  <xacro:property name="steer_joint_velocity_limit" value="2.83" />
  <xacro:property name="motor_wheel_mechanical_reduction" value="1.0" />

  <xacro:property name="wheel_joint_damping" value="0.1" />
  <xacro:property name="wheel_joint_friction" value="0.1" />
  <xacro:property name="wheel_joint_effort_limit" value="1000.0" />
  <xacro:property name="wheel_joint_velocity_limit" value="2000.0" />
  <xacro:property name="wheel_mechanical_reduction" value="1.0" />

  <xacro:macro name="cylinder_inertia" params="m r h">
    <inertia ixx="${m*(3*r*r+h*h)/12}" ixy = "0" ixz = "0" iyy="${m*(3*r*r+h*h)/12}" iyz = "0" izz="${m*r*r/2}" />
  </xacro:macro>

  <xacro:macro name="fixed_wheel" params="prefix parent *origin reflect hq">
    <!-- TODO: check reflect parameter -->
    <!--MOTOR WHEEL -->
    <joint name="${prefix}motor_wheel_joint" type="fixed">
      <parent link="${parent}"/>
      <child link="${prefix}motor_wheel"/>
      <xacro:insert_block name="origin" />
      <axis xyz="0 0 1" rpy="0 0 0" />
    </joint>
  

    <link name="${prefix}motor_wheel">
      <visual>
        <!-- HIGH RESOLUTION WHEELS -->
        <xacro:if value="${hq}">
		  <xacro:if value="${reflect}">
			<origin xyz="0 0 0.27952" rpy="0 0 ${M_PI}" />
		  </xacro:if>
		  <xacro:unless value="${reflect}">
			<origin xyz="0 0 0.27952" rpy="0 0 0.0" />
		  </xacro:unless>
          <geometry>            
            <mesh filename="package://rbvogui_description/meshes/wheels/hub_rbvogui_xl.stl" />
          </geometry> 
        </xacro:if>
         
        <!-- LOW RESOLUTION WHEELS -->
        <xacro:unless value="${hq}">
          <xacro:if value="${reflect}">
			<origin xyz="0 0 0.27952" rpy="0 0 ${M_PI}" />
		  </xacro:if>
		  <xacro:unless value="${reflect}">
			<origin xyz="0 0 0.27952" rpy="0 0 0.0" />
		  </xacro:unless>
          <geometry>
              <mesh filename="package://rbvogui_description/meshes/wheels/hub_rbvogui_xl.dae" />
          </geometry>
        </xacro:unless>
        <material name="red">
             <color rgba="0.9 0.1 0.1 1"/>     
        </material>
      </visual>

      <collision>
		<xacro:if value="${reflect}">
			<origin xyz="0 0 0.27952" rpy="0 0 ${M_PI}" />
		</xacro:if>
		<xacro:unless value="${reflect}">
			<origin xyz="0 0 0.27952" rpy="0 0 0.0" />
		</xacro:unless>
        <geometry>
            <mesh filename="package://rbvogui_description/meshes/wheels/hub_rbvogui_xl.dae" />
        </geometry>
      </collision>

      <inertial>
        <mass value="4" />
        <xacro:if value="${reflect}">
			<origin xyz="0 0 0.12" rpy="0 0 ${M_PI}"/>
		</xacro:if>
		<xacro:unless value="${reflect}">
			<origin xyz="0 0 0.12" rpy="0 0 0"/>
		</xacro:unless>
        <cylinder_inertia m="${wheel_mass}" r="${wheel_radius}" h="${wheel_width}" />
      </inertial>
    </link>

    <!--WHEEL TIRE -->
    <joint name="${prefix}wheel_joint" type="continuous">
      <parent link="${prefix}motor_wheel"/>
      <child link="${prefix}wheel"/>
      <origin xyz="0 0 0" rpy="0 0 ${M_PI}" />
      <xacro:if value="${reflect}">
		<axis xyz="0 -1 0" rpy="0 0 0" />
	  </xacro:if>
      <xacro:unless value="${reflect}">
		<axis xyz="0 1 0" rpy="0 0 0" />
	  </xacro:unless>
      <limit effort="${wheel_joint_effort_limit}" velocity="${wheel_joint_velocity_limit}"/>
      <joint_properties damping="${wheel_joint_damping}" friction="{wheel_joint_friction}"/>
    </joint>

    <transmission name="${prefix}wheel_trans">
      <type>transmission_interface/SimpleTransmission</type>
      <joint name="${prefix}wheel_joint">
        <hardwareInterface>hardware_interface/VelocityJointInterface</hardwareInterface>
      </joint>
      <actuator name="${prefix}wheel_motor">
        <hardwareInterface>hardware_interface/VelocityActuatorInterface</hardwareInterface>
        <mechanicalReduction>${wheel_mechanical_reduction}</mechanicalReduction>
      </actuator>
    </transmission>

    <link name="${prefix}wheel">
      <visual>
        <!-- HIGH RESOLUTION WHEELS -->
        <xacro:if value="${hq}">
		  <xacro:if value="${reflect}">
			<origin xyz="0 0 0" rpy="${M_PI} 0 0" />
		  </xacro:if>
		  <xacro:unless value="${reflect}">
			<origin xyz="0 0 0" rpy="0 0 0" />
		  </xacro:unless>
          
          <geometry>   
             <mesh filename="package://rbvogui_description/meshes/wheels/wheel_rbvogui_xl.stl" />   
          </geometry>
        </xacro:if>
        <!-- LOW RESOLUTION WHEELS -->
        <xacro:unless value="${hq}">
          <xacro:if value="${reflect}">
			<origin xyz="0 0 0" rpy="${M_PI} 0 0" />
		  </xacro:if>
		  <xacro:unless value="${reflect}">
			<origin xyz="0 0 0" rpy="0 0 0" />
		  </xacro:unless>
          
          <geometry>   
             <mesh filename="package://rbvogui_description/meshes/wheels/wheel_rbvogui_xl.dae" />   
          </geometry>
        </xacro:unless>
        <material name="black_wheel">
          <color rgba="0.1 0.1 0.1 1"/>     
        </material>
      </visual>

      <collision>
        <xacro:if value="${reflect}">
			<origin xyz="0 0 0" rpy="${M_PI} 0 0" />
		  </xacro:if>
		  <xacro:unless value="${reflect}">
			<origin xyz="0 0 0" rpy="0 0 0" />
		  </xacro:unless>
          <geometry>   
             <mesh filename="package://rbvogui_description/meshes/wheels/wheel_rbvogui_xl.dae" />   
          </geometry>
      </collision>

      <inertial>
        <mass value="${wheel_mass}" />
        <xacro:if value="${reflect}">
			<origin xyz="0 0 0" rpy="${M_PI/2 + M_PI} 0 0" />
		  </xacro:if>
		  <xacro:unless value="${reflect}">
			<origin xyz="0 0 0" rpy="${M_PI/2} 0 0" />
		  </xacro:unless>
         
        <cylinder_inertia m="${wheel_mass}" r="${wheel_radius}" h="${wheel_width}" />
      </inertial>
    </link>

    <xacro:gazebo_color_wheel prefix="${prefix}"/>
    <xacro:gazebo_color_steer_wheel prefix="${prefix}"/>

  </xacro:macro>

</robot>
